<?xml version="1.0" encoding="UTF-8" ?>
<robot name="arm">
    <link name="base_link">
        <visual>
            <origin xyz="0 0 0" rpy="0 0 0" />
            <geometry>
                <mesh filename="package://robotic-arm-refuelling/meshes/dofbot/base_link.STL" scale="5 5 5" />
            </geometry>
            <material name="">
                <color rgba="0.592156862745098 0.666666666666667 0.682352941176471 1" />
            </material>
        </visual>
        <collision>
            <origin xyz="0 0 0" rpy="0 0 0" />
            <geometry>
                <mesh filename="package://robotic-arm-refuelling/meshes/dofbot/base_link.STL" scale="5 5 5" />
            </geometry>
        </collision>
        <inertial>
           <mass value="10"/>
           <inertia ixx="8" ixy="0.0" ixz="0.0" iyy="4" iyz="0.0" izz="4"/>
        </inertial>
    </link>
    <link name="link1">
        <visual>
            <origin xyz="0 0 0" rpy="0 0 0" />
            <geometry>
                <mesh filename="package://robotic-arm-refuelling/meshes/dofbot/link1.STL" scale="5 5 5" />
            </geometry>
            <material name="">
                <color rgba="0 0.627450980392157 0.235294117647059 1" />
            </material>
        </visual>
        <collision>
            <origin xyz="0 0 0" rpy="0 0 0" />
            <geometry>
                <mesh filename="package://robotic-arm-refuelling/meshes/dofbot/link1.STL" scale="5 5 5" />
            </geometry>
        </collision>
        <inertial>
           <mass value="10"/>
           <inertia ixx="0.4" ixy="0.0" ixz="0.0" iyy="0.4" iyz="0.0" izz="0.4"/>
        </inertial>
    </link>
    <joint name="joint1" type="revolute">
        <origin xyz="0 0 0.33025" rpy="-0.010805 0 0" />
        <parent link="base_link" />
        <child link="link1" />
        <axis xyz="0 0 1" />
        <limit effort="30" velocity="1.0" lower="-1.5708" upper="1.5708"/>
    </joint>
    <link name="link2">
        <visual>
            <origin xyz="0 0 0" rpy="0 0 0" />
            <geometry>
                <mesh filename="package://robotic-arm-refuelling/meshes/dofbot/link2.STL" scale="5 5 5" />
            </geometry>
            <material name="">
                <color rgba="0.592156862745098 0.666666666666667 0.682352941176471 1" />
            </material>
        </visual>
        <collision>
            <origin xyz="0 0 0" rpy="0 0 0" />
            <geometry>
                <mesh filename="package://robotic-arm-refuelling/meshes/dofbot/link2.STL" scale="5 5 5" />
            </geometry>
        </collision>
        <inertial>
           <mass value="10"/>
           <inertia ixx="0.4" ixy="0.0" ixz="0.0" iyy="0.4" iyz="0.0" izz="0.4"/>
        </inertial>
    </link>
    <joint name="joint2" type="revolute">
        <origin xyz="0 -0.00159365 0.20725" rpy="0 1.5708 0" />
        <parent link="link1" />
        <child link="link2" />
        <axis xyz="0 0 1" />
        <limit effort="30" velocity="1.0" lower="-1.5708" upper="1.5708"/>
    </joint>
    <link name="link3">
        <visual>
            <origin xyz="0 0 0" rpy="0 0 0" />
            <geometry>
                <mesh filename="package://robotic-arm-refuelling/meshes/dofbot/link3.STL" scale="5 5 5" />
            </geometry>
            <material name="">
                <color rgba="0 0.627450980392157 0.235294117647059 1" />
            </material>
        </visual>
        <collision>
            <origin xyz="0 0 0" rpy="0 0 0" />
            <geometry>
                <mesh filename="package://robotic-arm-refuelling/meshes/dofbot/link3.STL" scale="5 5 5" />
            </geometry>
        </collision>
        <inertial>
           <mass value="10"/>
           <inertia ixx="0.4" ixy="0.0" ixz="0.0" iyy="0.4" iyz="0.0" izz="0.4"/>
        </inertial>
    </link>
    <joint name="joint3" type="revolute">
        <origin xyz="-0.41425 0 0" rpy="0 0 0" />
        <parent link="link2" />
        <child link="link3" />
        <axis xyz="0 0 1" />
        <limit effort="30" velocity="1.0" lower="-1.5708" upper="1.5708"/>
    </joint>
    <link name="link4">
        <visual>
            <origin xyz="0 0 0" rpy="0 0 0" />
            <geometry>
                <mesh filename="package://robotic-arm-refuelling/meshes/dofbot/link4.STL" scale="5 5 5" />
            </geometry>
            <material name="">
                <color rgba="0.592156862745098 0.666666666666667 0.682352941176471 1" />
            </material>
        </visual>
        <collision>
            <origin xyz="0 0 0" rpy="0 0 0" />
            <geometry>
                <mesh filename="package://robotic-arm-refuelling/meshes/dofbot/link4.STL" scale="5 5 5" />
            </geometry>
        </collision>
        <inertial>
           <mass value="10"/>
           <inertia ixx="0.4" ixy="0.0" ixz="0.0" iyy="0.4" iyz="0.0" izz="0.4"/>
        </inertial>
    </link>
    <joint name="joint4" type="revolute">
        <origin xyz="-0.41425 0 0" rpy="0 0 0.0083081" />
        <parent link="link3" />
        <child link="link4" />
        <axis xyz="0 0 1" />
        <limit effort="30" velocity="1.0" lower="-1.5708" upper="1.5708"/>
    </joint>
    <!-- link5 -->
    <link name="link5">
        <visual>
            <origin xyz="-0.2 0.075 0.2" rpy="3.14 0 0"/>
            <geometry>
                <mesh filename="package://robotic-arm-refuelling/meshes/refueller/injector.STL" scale="0.003 0.003 0.003" />
            </geometry>
            <material name="">
                <color rgba="1 1 1 1" />
            </material>
        </visual>
        <collision>
            <origin xyz="-0.2 0.075 0.2" rpy="3.14 0 0" />
            <geometry>
                <mesh filename="package://robotic-arm-refuelling/meshes/refueller/injector.STL" scale="0.003 0.003 0.003" />
            </geometry>
        </collision>
        <inertial>
           <mass value="10"/>
           <inertia ixx="0.4" ixy="0.0" ixz="0.0" iyy="0.4" iyz="0.0" izz="0.4"/>
        </inertial>
    </link>
    <!-- joint5 -->
    <joint name="joint5" type="revolute">
        <origin xyz="-0.36925 -0.005 0" rpy="0 -1.57 0"/>
        <axis xyz="0 0 1"/>
        <parent link="link4"/>
        <child link="link5"/>
        <limit effort="30" velocity="1.0" lower="-1.5708" upper="3.1416"/>
    </joint>

    <gazebo reference="base_link">
        <material>Gazebo/Black</material>
    </gazebo>
    <gazebo reference="link1">
        <material>Gazebo/Green</material>
    </gazebo>
    <gazebo reference="link2">
        <material>Gazebo/Black</material>
    </gazebo>
    <gazebo reference="link3">
        <material>Gazebo/Green</material>
    </gazebo>
    <gazebo reference="link4">
        <material>Gazebo/Black</material>
    </gazebo>
    <gazebo reference="link5">
        <material>Gazebo/White</material>
    </gazebo>

    <!-- PositionJointInterface -->
    <transmission name ="trans_1">
        <type>transmission_interface/SimpleTransmission</type>
        <joint name="joint1">
            <hardwareInterface>hardware_interface/PositionJointInterface</hardwareInterface>
        </joint>
        <actuator name="motor_1">
            <hardwareInterface>hardware_interface/PositionJointInterface</hardwareInterface>
            <mechanicalReduction>1</mechanicalReduction>
        </actuator>
    </transmission>

    <transmission name ="trans_2">
        <type>transmission_interface/SimpleTransmission</type>
        <joint name="joint2">
            <hardwareInterface>hardware_interface/PositionJointInterface</hardwareInterface>
        </joint>
        <actuator name="motor_2">
            <hardwareInterface>hardware_interface/PositionJointInterface</hardwareInterface>
            <mechanicalReduction>1</mechanicalReduction>
        </actuator>
    </transmission>
    <transmission name ="trans_3">
        <type>transmission_interface/SimpleTransmission</type>
        <joint name="joint3">
            <hardwareInterface>hardware_interface/PositionJointInterface</hardwareInterface>
        </joint>
        <actuator name="motor_3">
            <hardwareInterface>hardware_interface/PositionJointInterface</hardwareInterface>
            <mechanicalReduction>1</mechanicalReduction>
        </actuator>
    </transmission>
    <transmission name ="trans_4">
        <type>transmission_interface/SimpleTransmission</type>
        <joint name="joint4">
            <hardwareInterface>hardware_interface/PositionJointInterface</hardwareInterface>
        </joint>
        <actuator name="motor_4">
            <hardwareInterface>hardware_interface/PositionJointInterface</hardwareInterface>
            <mechanicalReduction>1</mechanicalReduction>
        </actuator>
    </transmission>
    <transmission name ="trans_5">
        <type>transmission_interface/SimpleTransmission</type>
        <joint name="joint5">
            <hardwareInterface>hardware_interface/PositionJointInterface</hardwareInterface>
        </joint>
        <actuator name="motor_5">
            <hardwareInterface>hardware_interface/PositionJointInterface</hardwareInterface>
            <mechanicalReduction>1</mechanicalReduction>
        </actuator>
    </transmission>

    <gazebo>
        <plugin name="control" filename="libgazebo_ros_control.so"/>
    </gazebo>

</robot>