<?xml version="1.0" ?>
<!-- =================================================================================== -->
<!-- |    This document was autogenerated by xacro from /home/sr42/catkin_ws/src/robotic-arm-refuelling/urdf/arm/arm.urdf.xacro | -->
<!-- |    EDITING THIS FILE BY HAND IS NOT RECOMMENDED                                 | -->
<!-- =================================================================================== -->
<robot name="arm">
    <link name="world" />
    <link name="base_link">
        <visual>
            <geometry>
                <cylinder length="0.05" radius="0.1" />
            </geometry>
            <material name="silver">
                <color rgba="0.75 0.75 0.75 1" />
            </material>
            <origin rpy="0 0 0" xyz="0 0 0.025" />
        </visual>
        <collision>
            <geometry>
                <cylinder length="0.05" radius="0.1" />
            </geometry>
            <origin rpy="0 0 0" xyz="0 0 0.025" />
        </collision>
        <inertial>
            <origin rpy="0 0 0" xyz="0 0 0.025" />
            <mass value="5.0" />
            <inertia ixx="0.0135" ixy="0.0" ixz="0.0" iyy="0.0135" iyz="0.0" izz="0.05" />
        </inertial>
    </link>
    <joint name="fixed" type="fixed">
        <parent link="world" />
        <child link="base_link" />
    </joint>
    <link name="link_1">
        <visual>
            <geometry>
                <cylinder length="0.5" radius="0.05" />
            </geometry>
            <material name="silver">
                <color rgba="0.75 0.75 0.75 1" />
            </material>
            <origin rpy="0 0 0" xyz="0 0 0.25" />
        </visual>
        <collision>
            <geometry>
                <cylinder length="0.5" radius="0.05" />
            </geometry>
            <origin rpy="0 0 0" xyz="0 0 0.25" />
        </collision>
        <inertial>
            <origin rpy="0 0 0" xyz="0 0 0.25" />
            <mass value="5.0" />
            <inertia ixx="0.107" ixy="0.0" ixz="0.0" iyy="0.107" iyz="0.0" izz="0.0125" />
        </inertial>
    </link>
    <joint name="joint1" type="continuous">
        <axis xyz="0 0 1" />
        <parent link="base_link" />
        <child link="link_1" />
        <origin rpy="0 0 0" xyz="0.0 0.0 0.05" />
    </joint>
    <link name="link_2">
        <inertial>
            <origin rpy="0 0 0" xyz="0 0 0.2" />
            <mass value="2.0" />
            <inertia ixx="0.027" ixy="0.0" ixz="0.0" iyy="0.027" iyz="0.0" izz="0.0025" />
        </inertial>
        <visual>
            <geometry>
                <cylinder length="0.4" radius="0.05" />
            </geometry>
            <material name="silver" />
            <origin rpy="0 0 0" xyz="0 0 0.2" />
        </visual>
        <collision>
            <geometry>
                <cylinder length="0.4" radius="0.05" />
            </geometry>
            <origin rpy="0 0 0" xyz="0 0 0.2" />
        </collision>
    </link>
    <joint name="joint2" type="continuous">
        <axis xyz="0 1 0" />
        <parent link="link_1" />
        <child link="link_2" />
        <origin rpy="0 0 0" xyz="0.0 -0.1 0.45" />
    </joint>
    <link name="link_3">
        <inertial>
            <origin rpy="0 0 0" xyz="0 0 0.2" />
            <mass value="2.0" />
            <inertia ixx="0.027" ixy="0.0" ixz="0.0" iyy="0.027" iyz="0.0" izz="0.0025" />
        </inertial>
        <visual>
            <geometry>
                <cylinder length="0.4" radius="0.05" />
            </geometry>
            <material name="silver" />
            <origin rpy="0 0 0" xyz="0 0 0.2" />
        </visual>
        <collision>
            <geometry>
                <cylinder length="0.4" radius="0.05" />
            </geometry>
            <origin rpy="0 0 0" xyz="0 0 0.2" />
        </collision>
    </link>
    <joint name="joint3" type="continuous">
        <axis xyz="0 1 0" />
        <parent link="link_2" />
        <child link="link_3" />
        <origin rpy="0 0 0" xyz="0.0 0.1 0.35" />
    </joint>
    <link name="link_4">
        <inertial>
            <origin rpy="0 0 0" xyz="0 0 0.2" />
            <mass value="2.0" />
            <inertia ixx="0.027" ixy="0.0" ixz="0.0" iyy="0.027" iyz="0.0" izz="0.0025" />
        </inertial>
        <visual>
            <geometry>
                <cylinder length="0.4" radius="0.05" />
            </geometry>
            <material name="silver" />
            <origin rpy="0 0 0" xyz="0 0 0.2" />
        </visual>
        <collision>
            <geometry>
                <cylinder length="0.4" radius="0.05" />
            </geometry>
            <origin rpy="0 0 0" xyz="0 0 0.2" />
        </collision>
    </link>
    <joint name="joint4" type="continuous">
        <axis xyz="0 1 0" />
        <parent link="link_3" />
        <child link="link_4" />
        <origin rpy="0 0 0" xyz="0.0 0.1 0.35" />
    </joint>
    <link name="camera_link" />
    <joint name="camera_joint" type="fixed">
        <parent link="link_4" />
        <child link="camera_link" />
        <origin rpy="1.57 -1.57 0" xyz="0 0 0.55" />
    </joint>
    <link name="link_5">
        <visual>
            <origin rpy="3.14 0 0" xyz="-0.2 0.06 0.58" />
            <geometry>
                <mesh filename="package://robotic-arm-refuelling/meshes/refueller/injector.stl" scale="0.003 0.003 0.003" />
            </geometry>
            <material name="">
                <color rgba="1 1 1 1" />
            </material>
        </visual>
        <collision>
            <origin rpy="3.14 0 0" xyz="-0.2 0.06 0.58" />
            <geometry>
                <mesh filename="package://robotic-arm-refuelling/meshes/refueller/injector.stl" scale="0.003 0.003 0.003" />
            </geometry>
        </collision>
        <inertial>
            <mass value="10" />
            <inertia ixx="0.4" ixy="0.0" ixz="0.0" iyy="0.4" iyz="0.0" izz="0.4" />
            <origin xyz="0 0 0" rpy="0 0 0" />
        </inertial>
    </link>
    <joint name="joint5" type="revolute">
        <origin rpy="0 0 0" xyz="0 0 0" />
        <axis xyz="0 0 1" />
        <parent link="link_4" />
        <child link="link_5" />
        <limit effort="30" lower="-1.5708" upper="3.1416" velocity="1.0" />
    </joint>
    <gazebo reference="base_link">
        <material>Gazebo/Black</material>
        <plugin name="gazebo_ros_control">
            <robotNamespace>/</robotNamespace>
        </plugin>
    </gazebo>
    <gazebo reference="link_1">
        <material>Gazebo/Grey</material>
    </gazebo>
    <gazebo reference="link_2">
        <material>Gazebo/Orange</material>
    </gazebo>
    <gazebo reference="link_3">
        <material>Gazebo/Black</material>
    </gazebo>
    <gazebo reference="link_4">
        <material>Gazebo/Yellow</material>
    </gazebo>
    <gazebo reference="camera_link">
        <material>Gazebo/Red</material>
    </gazebo>
    <!-- PositionJointInterface -->
    <transmission name="trans_1">
        <type>transmission_interface/SimpleTransmission</type>
        <joint name="joint1">
            <hardwareInterface>hardware_interface/PositionJointInterface</hardwareInterface>
        </joint>
        <actuator name="motor_1">
            <hardwareInterface>hardware_interface/PositionJointInterface</hardwareInterface>
            <mechanicalReduction>1</mechanicalReduction>
        </actuator>
    </transmission>
    <transmission name="trans_2">
        <type>transmission_interface/SimpleTransmission</type>
        <joint name="joint2">
            <hardwareInterface>hardware_interface/PositionJointInterface</hardwareInterface>
        </joint>
        <actuator name="motor_2">
            <hardwareInterface>hardware_interface/PositionJointInterface</hardwareInterface>
            <mechanicalReduction>1</mechanicalReduction>
        </actuator>
    </transmission>
    <transmission name="trans_3">
        <type>transmission_interface/SimpleTransmission</type>
        <joint name="joint3">
            <hardwareInterface>hardware_interface/PositionJointInterface</hardwareInterface>
        </joint>
        <actuator name="motor_3">
            <hardwareInterface>hardware_interface/PositionJointInterface</hardwareInterface>
            <mechanicalReduction>1</mechanicalReduction>
        </actuator>
    </transmission>
    <transmission name="trans_4">
        <type>transmission_interface/SimpleTransmission</type>
        <joint name="joint4">
            <hardwareInterface>hardware_interface/PositionJointInterface</hardwareInterface>
        </joint>
        <actuator name="motor_4">
            <hardwareInterface>hardware_interface/PositionJointInterface</hardwareInterface>
            <mechanicalReduction>1</mechanicalReduction>
        </actuator>
    </transmission>
    <transmission name="trans_5">
        <type>transmission_interface/SimpleTransmission</type>
        <joint name="joint5">
            <hardwareInterface>hardware_interface/PositionJointInterface</hardwareInterface>
        </joint>
        <actuator name="motor_5">
            <hardwareInterface>hardware_interface/PositionJointInterface</hardwareInterface>
            <mechanicalReduction>1</mechanicalReduction>
        </actuator>
    </transmission>
    <gazebo>
        <plugin filename="libgazebo_ros_control.so" name="control" />
    </gazebo>
    <gazebo reference="camera_link">
        <sensor name="camera" type="camera">
            <pose>0 0 0 0 0 0</pose>
            <visualize>true</visualize>
            <update_rate>10</update_rate>
            <camera>
                <horizontal_fov>1.089</horizontal_fov>
                <image>
                    <format>R8G8B8</format>
                    <width>640</width>
                    <height>480</height>
                </image>
                <clip>
                    <near>0.05</near>
                    <far>8.0</far>
                </clip>
            </camera>
            <plugin filename="libgazebo_ros_camera.so" name="camera_controller">
                <frame_name>camera_link_optical</frame_name>
            </plugin>
        </sensor>
    </gazebo>
</robot>

